Traceback (most recent call last):
  File "/Users/mmcc/opt/miniconda3/envs/snakes/lib/python3.11/site-packages/jupyter_cache/executors/utils.py", line 58, in single_nb_execution
    executenb(
  File "/Users/mmcc/opt/miniconda3/envs/snakes/lib/python3.11/site-packages/nbclient/client.py", line 1305, in execute
    return NotebookClient(nb=nb, resources=resources, km=km, **kwargs).execute()
           ^^^^^^^^^^^^^^^^^^^^^^^^^^^^^^^^^^^^^^^^^^^^^^^^^^^^^^^^^^^^^^^^^^^^^
  File "/Users/mmcc/opt/miniconda3/envs/snakes/lib/python3.11/site-packages/jupyter_core/utils/__init__.py", line 173, in wrapped
    return loop.run_until_complete(inner)
           ^^^^^^^^^^^^^^^^^^^^^^^^^^^^^^
  File "/Users/mmcc/opt/miniconda3/envs/snakes/lib/python3.11/asyncio/base_events.py", line 650, in run_until_complete
    return future.result()
           ^^^^^^^^^^^^^^^
  File "/Users/mmcc/opt/miniconda3/envs/snakes/lib/python3.11/contextlib.py", line 222, in __aexit__
    await self.gen.athrow(typ, value, traceback)
  File "/Users/mmcc/opt/miniconda3/envs/snakes/lib/python3.11/site-packages/nbclient/client.py", line 650, in async_setup_kernel
    yield
  File "/Users/mmcc/opt/miniconda3/envs/snakes/lib/python3.11/site-packages/nbclient/client.py", line 705, in async_execute
    await self.async_execute_cell(
  File "/Users/mmcc/opt/miniconda3/envs/snakes/lib/python3.11/site-packages/nbclient/client.py", line 1058, in async_execute_cell
    await self._check_raise_for_error(cell, cell_index, exec_reply)
  File "/Users/mmcc/opt/miniconda3/envs/snakes/lib/python3.11/site-packages/nbclient/client.py", line 914, in _check_raise_for_error
    raise CellExecutionError.from_cell_and_msg(cell, exec_reply_content)
nbclient.exceptions.CellExecutionError: An error occurred while executing the following cell:
------------------
series_df = netflix_df[netflix_df['series?'] == 1]
display(series_df.head(10))
------------------


[0;31m---------------------------------------------------------------------------[0m
[0;31mKeyError[0m                                  Traceback (most recent call last)
File [0;32m~/opt/miniconda3/envs/snakes/lib/python3.11/site-packages/pandas/core/indexes/base.py:3652[0m, in [0;36mIndex.get_loc[0;34m(self, key)[0m
[1;32m   3651[0m [38;5;28;01mtry[39;00m:
[0;32m-> 3652[0m     [38;5;28;01mreturn[39;00m [38;5;28mself[39m[38;5;241m.[39m_engine[38;5;241m.[39mget_loc(casted_key)
[1;32m   3653[0m [38;5;28;01mexcept[39;00m [38;5;167;01mKeyError[39;00m [38;5;28;01mas[39;00m err:

File [0;32m~/opt/miniconda3/envs/snakes/lib/python3.11/site-packages/pandas/_libs/index.pyx:147[0m, in [0;36mpandas._libs.index.IndexEngine.get_loc[0;34m()[0m

File [0;32m~/opt/miniconda3/envs/snakes/lib/python3.11/site-packages/pandas/_libs/index.pyx:176[0m, in [0;36mpandas._libs.index.IndexEngine.get_loc[0;34m()[0m

File [0;32mpandas/_libs/hashtable_class_helper.pxi:7080[0m, in [0;36mpandas._libs.hashtable.PyObjectHashTable.get_item[0;34m()[0m

File [0;32mpandas/_libs/hashtable_class_helper.pxi:7088[0m, in [0;36mpandas._libs.hashtable.PyObjectHashTable.get_item[0;34m()[0m

[0;31mKeyError[0m: 'series?'

The above exception was the direct cause of the following exception:

[0;31mKeyError[0m                                  Traceback (most recent call last)
Cell [0;32mIn[19], line 1[0m
[0;32m----> 1[0m series_df [38;5;241m=[39m netflix_df[netflix_df[[38;5;124m'[39m[38;5;124mseries?[39m[38;5;124m'[39m] [38;5;241m==[39m [38;5;241m1[39m]
[1;32m      2[0m display(series_df[38;5;241m.[39mhead([38;5;241m10[39m))

File [0;32m~/opt/miniconda3/envs/snakes/lib/python3.11/site-packages/pandas/core/frame.py:3761[0m, in [0;36mDataFrame.__getitem__[0;34m(self, key)[0m
[1;32m   3759[0m [38;5;28;01mif[39;00m [38;5;28mself[39m[38;5;241m.[39mcolumns[38;5;241m.[39mnlevels [38;5;241m>[39m [38;5;241m1[39m:
[1;32m   3760[0m     [38;5;28;01mreturn[39;00m [38;5;28mself[39m[38;5;241m.[39m_getitem_multilevel(key)
[0;32m-> 3761[0m indexer [38;5;241m=[39m [38;5;28mself[39m[38;5;241m.[39mcolumns[38;5;241m.[39mget_loc(key)
[1;32m   3762[0m [38;5;28;01mif[39;00m is_integer(indexer):
[1;32m   3763[0m     indexer [38;5;241m=[39m [indexer]

File [0;32m~/opt/miniconda3/envs/snakes/lib/python3.11/site-packages/pandas/core/indexes/base.py:3654[0m, in [0;36mIndex.get_loc[0;34m(self, key)[0m
[1;32m   3652[0m     [38;5;28;01mreturn[39;00m [38;5;28mself[39m[38;5;241m.[39m_engine[38;5;241m.[39mget_loc(casted_key)
[1;32m   3653[0m [38;5;28;01mexcept[39;00m [38;5;167;01mKeyError[39;00m [38;5;28;01mas[39;00m err:
[0;32m-> 3654[0m     [38;5;28;01mraise[39;00m [38;5;167;01mKeyError[39;00m(key) [38;5;28;01mfrom[39;00m [38;5;21;01merr[39;00m
[1;32m   3655[0m [38;5;28;01mexcept[39;00m [38;5;167;01mTypeError[39;00m:
[1;32m   3656[0m     [38;5;66;03m# If we have a listlike key, _check_indexing_error will raise[39;00m
[1;32m   3657[0m     [38;5;66;03m#  InvalidIndexError. Otherwise we fall through and re-raise[39;00m
[1;32m   3658[0m     [38;5;66;03m#  the TypeError.[39;00m
[1;32m   3659[0m     [38;5;28mself[39m[38;5;241m.[39m_check_indexing_error(key)

[0;31mKeyError[0m: 'series?'

