Traceback (most recent call last):
  File "/Users/mmcc/opt/miniconda3/envs/snakes/lib/python3.11/site-packages/jupyter_cache/executors/utils.py", line 58, in single_nb_execution
    executenb(
  File "/Users/mmcc/opt/miniconda3/envs/snakes/lib/python3.11/site-packages/nbclient/client.py", line 1305, in execute
    return NotebookClient(nb=nb, resources=resources, km=km, **kwargs).execute()
           ^^^^^^^^^^^^^^^^^^^^^^^^^^^^^^^^^^^^^^^^^^^^^^^^^^^^^^^^^^^^^^^^^^^^^
  File "/Users/mmcc/opt/miniconda3/envs/snakes/lib/python3.11/site-packages/jupyter_core/utils/__init__.py", line 173, in wrapped
    return loop.run_until_complete(inner)
           ^^^^^^^^^^^^^^^^^^^^^^^^^^^^^^
  File "/Users/mmcc/opt/miniconda3/envs/snakes/lib/python3.11/asyncio/base_events.py", line 650, in run_until_complete
    return future.result()
           ^^^^^^^^^^^^^^^
  File "/Users/mmcc/opt/miniconda3/envs/snakes/lib/python3.11/contextlib.py", line 222, in __aexit__
    await self.gen.athrow(typ, value, traceback)
  File "/Users/mmcc/opt/miniconda3/envs/snakes/lib/python3.11/site-packages/nbclient/client.py", line 650, in async_setup_kernel
    yield
  File "/Users/mmcc/opt/miniconda3/envs/snakes/lib/python3.11/site-packages/nbclient/client.py", line 705, in async_execute
    await self.async_execute_cell(
  File "/Users/mmcc/opt/miniconda3/envs/snakes/lib/python3.11/site-packages/nbclient/client.py", line 1058, in async_execute_cell
    await self._check_raise_for_error(cell, cell_index, exec_reply)
  File "/Users/mmcc/opt/miniconda3/envs/snakes/lib/python3.11/site-packages/nbclient/client.py", line 914, in _check_raise_for_error
    raise CellExecutionError.from_cell_and_msg(cell, exec_reply_content)
nbclient.exceptions.CellExecutionError: An error occurred while executing the following cell:
------------------
new_dishes = ['quesadilla', 'jollof rice', 'grilled chili peppers', 'ma la fish', 'schnitzel', 'empanadas']
new_ser = pd.Series(new_dishes, name='dish')
print(new_ser)

print(menu_ser.append(new_ser))
------------------


[0;31m---------------------------------------------------------------------------[0m
[0;31mAttributeError[0m                            Traceback (most recent call last)
[0;32m/var/folders/6s/cpr1t_711kj905fk6qjplyrw0000gr/T/ipykernel_61172/2769499521.py[0m in [0;36m?[0;34m()[0m
[1;32m      1[0m [0mnew_dishes[0m [0;34m=[0m [0;34m[[0m[0;34m'quesadilla'[0m[0;34m,[0m [0;34m'jollof rice'[0m[0;34m,[0m [0;34m'grilled chili peppers'[0m[0;34m,[0m [0;34m'ma la fish'[0m[0;34m,[0m [0;34m'schnitzel'[0m[0;34m,[0m [0;34m'empanadas'[0m[0;34m][0m[0;34m[0m[0;34m[0m[0m
[1;32m      2[0m [0mnew_ser[0m [0;34m=[0m [0mpd[0m[0;34m.[0m[0mSeries[0m[0;34m([0m[0mnew_dishes[0m[0;34m,[0m [0mname[0m[0;34m=[0m[0;34m'dish'[0m[0;34m)[0m[0;34m[0m[0;34m[0m[0m
[1;32m      3[0m [0mprint[0m[0;34m([0m[0mnew_ser[0m[0;34m)[0m[0;34m[0m[0;34m[0m[0m
[1;32m      4[0m [0;34m[0m[0m
[0;32m----> 5[0;31m [0mprint[0m[0;34m([0m[0mmenu_ser[0m[0;34m.[0m[0mappend[0m[0;34m([0m[0mnew_ser[0m[0;34m)[0m[0;34m)[0m[0;34m[0m[0;34m[0m[0m
[0m
[0;32m~/opt/miniconda3/envs/snakes/lib/python3.11/site-packages/pandas/core/generic.py[0m in [0;36m?[0;34m(self, name)[0m
[1;32m   5985[0m             [0;32mand[0m [0mname[0m [0;32mnot[0m [0;32min[0m [0mself[0m[0;34m.[0m[0m_accessors[0m[0;34m[0m[0;34m[0m[0m
[1;32m   5986[0m             [0;32mand[0m [0mself[0m[0;34m.[0m[0m_info_axis[0m[0;34m.[0m[0m_can_hold_identifiers_and_holds_name[0m[0;34m([0m[0mname[0m[0;34m)[0m[0;34m[0m[0;34m[0m[0m
[1;32m   5987[0m         ):
[1;32m   5988[0m             [0;32mreturn[0m [0mself[0m[0;34m[[0m[0mname[0m[0;34m][0m[0;34m[0m[0;34m[0m[0m
[0;32m-> 5989[0;31m         [0;32mreturn[0m [0mobject[0m[0;34m.[0m[0m__getattribute__[0m[0;34m([0m[0mself[0m[0;34m,[0m [0mname[0m[0;34m)[0m[0;34m[0m[0;34m[0m[0m
[0m
[0;31mAttributeError[0m: 'Series' object has no attribute 'append'

