Traceback (most recent call last):
  File "/Users/mmcc/opt/miniconda3/lib/python3.10/site-packages/jupyter_cache/executors/utils.py", line 58, in single_nb_execution
    executenb(
  File "/Users/mmcc/opt/miniconda3/lib/python3.10/site-packages/nbclient/client.py", line 1314, in execute
    return NotebookClient(nb=nb, resources=resources, km=km, **kwargs).execute()
  File "/Users/mmcc/opt/miniconda3/lib/python3.10/site-packages/jupyter_core/utils/__init__.py", line 165, in wrapped
    return loop.run_until_complete(inner)
  File "/Users/mmcc/opt/miniconda3/lib/python3.10/asyncio/base_events.py", line 649, in run_until_complete
    return future.result()
  File "/Users/mmcc/opt/miniconda3/lib/python3.10/site-packages/nbclient/client.py", line 709, in async_execute
    await self.async_execute_cell(
  File "/Users/mmcc/opt/miniconda3/lib/python3.10/site-packages/nbclient/client.py", line 1062, in async_execute_cell
    await self._check_raise_for_error(cell, cell_index, exec_reply)
  File "/Users/mmcc/opt/miniconda3/lib/python3.10/site-packages/nbclient/client.py", line 918, in _check_raise_for_error
    raise CellExecutionError.from_cell_and_msg(cell, exec_reply_content)
nbclient.exceptions.CellExecutionError: An error occurred while executing the following cell:
------------------
import numpy as np
import matplotlib.pyplot as plt

infile = open('data_files/dice_data.txt', 'r')
total_rolls = []

line = infile.readline()
line = infile.readline()
while len(line) > 1:
    line_arr = line.split(',')
    total = int(line_arr[1]) + int(line_arr[2]) 
    total_rolls.append(total)
    line = infile.readline()

infile.close()

total_arr = np.array(total_rolls)

plt.hist(total_arr, range=(0,13), bins=13, histtype='step')
plt.xlabel('total of 2 dice')
plt.ylabel('number of times rolled')
plt.title('dice roll outcomes')
plt.show()
------------------


[0;31m---------------------------------------------------------------------------[0m
[0;31mModuleNotFoundError[0m                       Traceback (most recent call last)
Cell [0;32mIn[1], line 2[0m
[1;32m      1[0m [38;5;28;01mimport[39;00m [38;5;21;01mnumpy[39;00m [38;5;28;01mas[39;00m [38;5;21;01mnp[39;00m
[0;32m----> 2[0m [38;5;28;01mimport[39;00m [38;5;21;01mmatplotlib[39;00m[38;5;21;01m.[39;00m[38;5;21;01mpyplot[39;00m [38;5;28;01mas[39;00m [38;5;21;01mplt[39;00m
[1;32m      4[0m infile [38;5;241m=[39m [38;5;28mopen[39m([38;5;124m'[39m[38;5;124mdata_files/dice_data.txt[39m[38;5;124m'[39m, [38;5;124m'[39m[38;5;124mr[39m[38;5;124m'[39m)
[1;32m      5[0m total_rolls [38;5;241m=[39m []

[0;31mModuleNotFoundError[0m: No module named 'matplotlib'

